<?xml version="1.0"?>
<robot xmlns:xacro="http://www.ros.org/wiki/xacro" name="velodyne_example">
  <xacro:arg name="gpu" default="false"/>
  <xacro:property name="gpu" value="$(arg gpu)" />
  <xacro:arg name="organize_cloud" default="false"/>
  <xacro:property name="organize_cloud" value="$(arg organize_cloud)" />
  <material name="black">
        <color rgba="0.0 0.0 0.0 1.0"/>
    </material>

    <material name="dark">
      <color rgba="0.3 0.3 0.3 1.0"/>
    </material>
  <!-- Base Footprint -->
  <link name="base_footprint" />

  <!-- Base Link -->
  <joint name="footprint" type="fixed" >
   <parent link="base_footprint"/>
    <child link="base_link" />
    <origin xyz="0 0 0.1" rpy="0 0 0" />
  </joint>
  <link name="base_link" >
    <visual>
      <geometry>
        <box size="0.5 0.5 0.05" />
      </geometry>
    </visual>
    <collision>
      <geometry>
        <box size="0.5 0.5 0.05" />
      </geometry>

    </collision>
    <inertial>
      <origin xyz="0 0 0"/>
      <mass value="10"/>
      <inertia ixx="3.0" ixy="0.0" ixz="0.0"
               iyy="3.0" iyz="0.0" 
               izz="3.0" />
    </inertial>
  </link>

<joint name="wheel_left_joint" type="continuous">
    <parent link="base_link"/>
    <child link="wheel_left_link"/>
    <origin xyz="0.2 0.3 0.0" rpy="-1.57 0 0"/>
    <axis xyz="0 0 1"/>
  </joint>

  <link name="wheel_left_link">
    <visual>
      <origin xyz="0 0 0" rpy="1.57 0 0"/>
      <geometry>
        <mesh filename="package://velodyne_description/meshes/wheels/left_tire.stl" scale="0.003 0.003 0.003"/>
      </geometry>
      <material name="dark"/>
    </visual>

    <collision>
      <origin xyz="0 0 0" rpy="0 0 0"/>
      <geometry>
        <cylinder length="0.018" radius="0.1"/>
      </geometry>
    </collision>

    <inertial>
      <origin xyz="0 0 0" />
      <mass value="2.8498940e-02" />
      <inertia ixx="1.1175580e-05" ixy="-4.2369783e-11" ixz="-5.9381719e-09"
               iyy="1.1192413e-05" iyz="-1.4400107e-11"
               izz="2.0712558e-05" />
      </inertial>
  </link>

  <joint name="wheel_right_joint" type="continuous">
    <parent link="base_link"/>
    <child link="wheel_right_link"/>
    <origin xyz="0.2 -0.3 0.0" rpy="-1.57 0 0"/>
    <axis xyz="0 0 1"/>
  </joint>

  <link name="wheel_right_link">
    <visual>
      <origin xyz="0 0 0" rpy="1.57 0 0"/>
      <geometry>
        <mesh filename="package://velodyne_description/meshes/wheels/right_tire.stl" scale="0.003 0.003 0.003"/>
      </geometry>
      <material name="dark"/>
    </visual>

    <collision>
      <origin xyz="0 0 0" rpy="0 0 0"/>
      <geometry>
        <cylinder length="0.018" radius="0.1"/>
      </geometry>
    </collision>

    <inertial>
      <origin xyz="0 0 0" />
      <mass value="2.8498940e-02" />
      <inertia ixx="1.1175580e-05" ixy="-4.2369783e-11" ixz="-5.9381719e-09"
               iyy="1.1192413e-05" iyz="-1.4400107e-11"
               izz="2.0712558e-05" />
      </inertial>
  </link>

  <joint name="caster_back_right_joint" type="fixed">
    <parent link="base_link"/>
    <child link="caster_back_right_link"/>
    <origin xyz="-0.2 -0.064 -0.1" rpy="-1.57 0 0"/>
  </joint>

  <link name="caster_back_right_link">
    <collision>
      <origin xyz="0 0.001 0" rpy="0 0 0"/>
      <geometry>
        <box size="0.050 0.009 0.06"/>
      </geometry>
    </collision>

    <inertial>
      <origin xyz="0 0 0" />
      <mass value="0.005" />
      <inertia ixx="0.001" ixy="0.0" ixz="0.0"
               iyy="0.001" iyz="0.0"
               izz="0.001" />
    </inertial>
  </link>
  <gazebo reference="caster_back_right_link">
      <mu1>0</mu1>
      <mu2>0</mu2>
  </gazebo>

  <joint name="caster_back_left_joint" type="fixed">
    <parent link="base_link"/>
    <child link="caster_back_left_link"/>
    <origin xyz="-0.2 0.064 -0.1" rpy="-1.57 0 0"/>
  </joint>

  <link name="caster_back_left_link">
    <collision>
      <origin xyz="0 0.001 0" rpy="0 0 0"/>
      <geometry>
        <box size="0.050 0.009 0.06"/>
      </geometry>
    </collision>

    <inertial>
      <origin xyz="0 0 0" />
      <mass value="0.005" />
      <inertia ixx="0.001" ixy="0.0" ixz="0.0"
               iyy="0.001" iyz="0.0"
               izz="0.001" />
    </inertial>
  </link>
  <gazebo reference="caster_back_left_link">
      <mu1>0</mu1>
      <mu2>0</mu2>
  </gazebo>

    <gazebo>
      <plugin name="velodyne_controller" filename="libgazebo_ros_diff_drive.so">
        <commandTopic>cmd_vel</commandTopic>
        <odometryTopic>odom</odometryTopic>
        <odometryFrame>odom</odometryFrame>
        <odometrySource>world</odometrySource>
        <publishOdomTF>true</publishOdomTF>
        <robotBaseFrame>base_footprint</robotBaseFrame>
        <publishWheelTF>true</publishWheelTF>
        <publishWheelJointState>true</publishWheelJointState>
        <publishTf>true</publishTf>
        <legacyMode>false</legacyMode>
        <updateRate>50</updateRate>
        <leftJoint>wheel_left_joint</leftJoint>
        <rightJoint>wheel_right_joint</rightJoint>
        <wheelSeparation>0.160</wheelSeparation>
        <wheelDiameter>0.066</wheelDiameter>
        <wheelAcceleration>1</wheelAcceleration>
        <wheelTorque>10</wheelTorque>
        <rosDebugLevel>na</rosDebugLevel>
      </plugin>
    </gazebo>

  <xacro:include filename="$(find velodyne_description)/urdf/VLP-16.urdf.xacro"/>
  <xacro:include filename="$(find velodyne_description)/urdf/imu.urdf.xacro"/>
  <xacro:VLP-16 parent="base_link" name="velodyne" topic="/velodyne_points" organize_cloud="${organize_cloud}" hz="10" samples="440" gpu="${gpu}">
    <origin xyz="0 0 0.4" rpy="0 0 0" />
  </xacro:VLP-16>
  <xacro:imu_sensor xyz="-0.1 0 ${0.04 + 0.01}"
                    rpy="0 0 0"
                    parent="base_link">
      </xacro:imu_sensor>

</robot>
